Traceback (most recent call last):
  File "/Users/kjersti.daae/Library/CloudStorage/OneDrive-UniversityofBergen/KDA/Courses/GEOF211/GEOF211_compendium/.venv/lib/python3.9/site-packages/jupyter_core/utils/__init__.py", line 154, in wrapped
    asyncio.get_running_loop()
RuntimeError: no running event loop

During handling of the above exception, another exception occurred:

Traceback (most recent call last):
  File "/Users/kjersti.daae/Library/CloudStorage/OneDrive-UniversityofBergen/KDA/Courses/GEOF211/GEOF211_compendium/.venv/lib/python3.9/site-packages/jupyter_cache/executors/utils.py", line 58, in single_nb_execution
    executenb(
  File "/Users/kjersti.daae/Library/CloudStorage/OneDrive-UniversityofBergen/KDA/Courses/GEOF211/GEOF211_compendium/.venv/lib/python3.9/site-packages/nbclient/client.py", line 1319, in execute
    return NotebookClient(nb=nb, resources=resources, km=km, **kwargs).execute()
  File "/Users/kjersti.daae/Library/CloudStorage/OneDrive-UniversityofBergen/KDA/Courses/GEOF211/GEOF211_compendium/.venv/lib/python3.9/site-packages/jupyter_core/utils/__init__.py", line 158, in wrapped
    return loop.run_until_complete(inner)
  File "/Library/Developer/CommandLineTools/Library/Frameworks/Python3.framework/Versions/3.9/lib/python3.9/asyncio/base_events.py", line 642, in run_until_complete
    return future.result()
  File "/Users/kjersti.daae/Library/CloudStorage/OneDrive-UniversityofBergen/KDA/Courses/GEOF211/GEOF211_compendium/.venv/lib/python3.9/site-packages/nbclient/client.py", line 709, in async_execute
    await self.async_execute_cell(
  File "/Users/kjersti.daae/Library/CloudStorage/OneDrive-UniversityofBergen/KDA/Courses/GEOF211/GEOF211_compendium/.venv/lib/python3.9/site-packages/nbclient/client.py", line 1062, in async_execute_cell
    await self._check_raise_for_error(cell, cell_index, exec_reply)
  File "/Users/kjersti.daae/Library/CloudStorage/OneDrive-UniversityofBergen/KDA/Courses/GEOF211/GEOF211_compendium/.venv/lib/python3.9/site-packages/nbclient/client.py", line 918, in _check_raise_for_error
    raise CellExecutionError.from_cell_and_msg(cell, exec_reply_content)
nbclient.exceptions.CellExecutionError: An error occurred while executing the following cell:
------------------
import numpy as np
import matplotlib.pyplot as plt

# Create time values
Fs=100 # sampling rate -. number of samples per second
t = np.arange(0,1,1/Fs) #one cycle

#define frequencies, phases, and amplitudes of three sine waves
frequencies=np.array([2.,5.,10])
amplitudes=np.array([1.,2.,4.])

# compute the wave signals
wave1 = amplitudes[0] * np.sin(2 * np.pi * frequencies[0] * t)
wave2 = amplitudes[1] * np.sin(2 * np.pi * frequencies[1] * t)
wave3 = amplitudes[2] * np.sin(2 * np.pi * frequencies[2] * t)

# Add the sine waves together
superposition_wave = wave1 + wave2 + wave3

#plot the wave signals
fig, ax = plt.subplots(2, 1, figsize=(7, 6), sharex=True)
ax[0].set_xlim(( 0, 1))
ax[0].set_ylim((-7.5, 7.5))

line1, = ax[0].plot(t, wave1,'-', lw = 1, label='wave 1')
line2, = ax[0].plot(t, wave2,'--', lw = 1, label='wave 2')
line3, = ax[0].plot(t, wave3,':', lw = 1, label='wave 3')

ax[1].plot(t, wave1,'-',color='darkgrey', lw = 1, label='wave 1')
ax[1].plot(t, wave2,'--',color='darkgrey', lw = 1, label='wave 2')
ax[1].plot(t, wave3,':',color='darkgrey',lw = 1, label='wave 3')
line4, = ax[1].plot(t, superposition_wave,'k', lw = 3, label='Superposition')

ax[0].set_ylabel('Amplitude')
ax[0].set_title("Initial Condition")
ax[0].legend(loc="upper right", bbox_to_anchor=(1.1, 1))
ax[1].legend(loc="upper right", bbox_to_anchor=(1.1, 1))
ax[1].set_ylabel('Amplitude')
ax[1].set_xlabel('time, t [s]')
ax[1].set_ylim((-7.5, 7.5))
------------------


[0;31m---------------------------------------------------------------------------[0m
[0;31mModuleNotFoundError[0m                       Traceback (most recent call last)
Cell [0;32mIn[1], line 1[0m
[0;32m----> 1[0m [38;5;28;01mimport[39;00m[38;5;250m [39m[38;5;21;01mnumpy[39;00m[38;5;250m [39m[38;5;28;01mas[39;00m[38;5;250m [39m[38;5;21;01mnp[39;00m
[1;32m      2[0m [38;5;28;01mimport[39;00m[38;5;250m [39m[38;5;21;01mmatplotlib[39;00m[38;5;21;01m.[39;00m[38;5;21;01mpyplot[39;00m[38;5;250m [39m[38;5;28;01mas[39;00m[38;5;250m [39m[38;5;21;01mplt[39;00m
[1;32m      4[0m [38;5;66;03m# Create time values[39;00m

[0;31mModuleNotFoundError[0m: No module named 'numpy'

