Traceback (most recent call last):
  File "C:\Users\kda005\Anaconda3\envs\GEOF211_compendium\Lib\site-packages\jupyter_cache\executors\utils.py", line 58, in single_nb_execution
    executenb(
  File "C:\Users\kda005\Anaconda3\envs\GEOF211_compendium\Lib\site-packages\nbclient\client.py", line 1314, in execute
    return NotebookClient(nb=nb, resources=resources, km=km, **kwargs).execute()
           ^^^^^^^^^^^^^^^^^^^^^^^^^^^^^^^^^^^^^^^^^^^^^^^^^^^^^^^^^^^^^^^^^^^^^
  File "C:\Users\kda005\Anaconda3\envs\GEOF211_compendium\Lib\site-packages\jupyter_core\utils\__init__.py", line 165, in wrapped
    return loop.run_until_complete(inner)
           ^^^^^^^^^^^^^^^^^^^^^^^^^^^^^^
  File "C:\Users\kda005\Anaconda3\envs\GEOF211_compendium\Lib\asyncio\base_events.py", line 687, in run_until_complete
    return future.result()
           ^^^^^^^^^^^^^^^
  File "C:\Users\kda005\Anaconda3\envs\GEOF211_compendium\Lib\site-packages\nbclient\client.py", line 709, in async_execute
    await self.async_execute_cell(
  File "C:\Users\kda005\Anaconda3\envs\GEOF211_compendium\Lib\site-packages\nbclient\client.py", line 1062, in async_execute_cell
    await self._check_raise_for_error(cell, cell_index, exec_reply)
  File "C:\Users\kda005\Anaconda3\envs\GEOF211_compendium\Lib\site-packages\nbclient\client.py", line 918, in _check_raise_for_error
    raise CellExecutionError.from_cell_and_msg(cell, exec_reply_content)
nbclient.exceptions.CellExecutionError: An error occurred while executing the following cell:
------------------
from scipy.fft import fft

# Compute the Fourier transform
superposition_wave_fft = fft(superposition_wave)

# Frequency values for the Fourier transform
sampling_rate = 1 / (t[1] - t[0]) #1 sample per second
frequencies = np.fft.fftfreq(len(t), d=1/sampling_rate)

# Plot the Fourier transform
plt.figure(figsize=(8, 6))
plt.plot(frequencies, np.abs(superposition_wave_fft),'k',lw=2, label="Fourier Transform")
plt.xlim([-3*np.p1,3*np.pi])
plt.xlabel("Frequency (Hz)")
plt.ylabel("Amplitude")
plt.title("Fourier Transform of superposition wave")
------------------


[1;31m---------------------------------------------------------------------------[0m
[1;31mAttributeError[0m                            Traceback (most recent call last)
Cell [1;32mIn[2], line 13[0m
[0;32m     11[0m plt[38;5;241m.[39mfigure(figsize[38;5;241m=[39m([38;5;241m8[39m, [38;5;241m6[39m))
[0;32m     12[0m plt[38;5;241m.[39mplot(frequencies, np[38;5;241m.[39mabs(superposition_wave_fft),[38;5;124m'[39m[38;5;124mk[39m[38;5;124m'[39m,lw[38;5;241m=[39m[38;5;241m2[39m, label[38;5;241m=[39m[38;5;124m"[39m[38;5;124mFourier Transform[39m[38;5;124m"[39m)
[1;32m---> 13[0m plt[38;5;241m.[39mxlim([[38;5;241m-[39m[38;5;241m3[39m[38;5;241m*[39m[43mnp[49m[38;5;241;43m.[39;49m[43mp1[49m,[38;5;241m3[39m[38;5;241m*[39mnp[38;5;241m.[39mpi])
[0;32m     14[0m plt[38;5;241m.[39mxlabel([38;5;124m"[39m[38;5;124mFrequency (Hz)[39m[38;5;124m"[39m)
[0;32m     15[0m plt[38;5;241m.[39mylabel([38;5;124m"[39m[38;5;124mAmplitude[39m[38;5;124m"[39m)

File [1;32m~\Anaconda3\envs\GEOF211_compendium\Lib\site-packages\numpy\__init__.py:333[0m, in [0;36m__getattr__[1;34m(attr)[0m
[0;32m    330[0m     [38;5;124m"[39m[38;5;124mRemoved in NumPy 1.25.0[39m[38;5;124m"[39m
[0;32m    331[0m     [38;5;28;01mraise[39;00m [38;5;167;01mRuntimeError[39;00m([38;5;124m"[39m[38;5;124mTester was removed in NumPy 1.25.[39m[38;5;124m"[39m)
[1;32m--> 333[0m [38;5;28;01mraise[39;00m [38;5;167;01mAttributeError[39;00m([38;5;124m"[39m[38;5;124mmodule [39m[38;5;132;01m{!r}[39;00m[38;5;124m has no attribute [39m[38;5;124m"[39m
[0;32m    334[0m                      [38;5;124m"[39m[38;5;132;01m{!r}[39;00m[38;5;124m"[39m[38;5;241m.[39mformat([38;5;18m__name__[39m, attr))

[1;31mAttributeError[0m: module 'numpy' has no attribute 'p1'

