Traceback (most recent call last):
  File "C:\Users\kda005\Anaconda3\envs\GEOF211_compendium\Lib\site-packages\jupyter_cache\executors\utils.py", line 58, in single_nb_execution
    executenb(
  File "C:\Users\kda005\Anaconda3\envs\GEOF211_compendium\Lib\site-packages\nbclient\client.py", line 1314, in execute
    return NotebookClient(nb=nb, resources=resources, km=km, **kwargs).execute()
           ^^^^^^^^^^^^^^^^^^^^^^^^^^^^^^^^^^^^^^^^^^^^^^^^^^^^^^^^^^^^^^^^^^^^^
  File "C:\Users\kda005\Anaconda3\envs\GEOF211_compendium\Lib\site-packages\jupyter_core\utils\__init__.py", line 165, in wrapped
    return loop.run_until_complete(inner)
           ^^^^^^^^^^^^^^^^^^^^^^^^^^^^^^
  File "C:\Users\kda005\Anaconda3\envs\GEOF211_compendium\Lib\asyncio\base_events.py", line 687, in run_until_complete
    return future.result()
           ^^^^^^^^^^^^^^^
  File "C:\Users\kda005\Anaconda3\envs\GEOF211_compendium\Lib\site-packages\nbclient\client.py", line 709, in async_execute
    await self.async_execute_cell(
  File "C:\Users\kda005\Anaconda3\envs\GEOF211_compendium\Lib\site-packages\nbclient\client.py", line 1062, in async_execute_cell
    await self._check_raise_for_error(cell, cell_index, exec_reply)
  File "C:\Users\kda005\Anaconda3\envs\GEOF211_compendium\Lib\site-packages\nbclient\client.py", line 918, in _check_raise_for_error
    raise CellExecutionError.from_cell_and_msg(cell, exec_reply_content)
nbclient.exceptions.CellExecutionError: An error occurred while executing the following cell:
------------------
import numpy as np
import matplotlib.pyplot as plt

t = np.arange(0,5,0.001)

square_wave = 1 - 2 * (t.astype(int) % 2)

N = 10 #number of frequencies to include
fsq = np.zeros_like(t) #fsw short for frequencies

for i in range(N): #loop through the 20 first sine waves
    n = 2*i + 1
    fsq += np.sin(n * np.pi *t) / n #adds the sine wave for n into the sum
fsq *= 4 / np.pi

fig, ax = plt.subplots()
ax.plot(t, square_wave,'k', lw=2,label='true signal')
ax.plot(t, fsq, 'r',lw=1, label='Fourier series, n=10')
ax.set_ylim(-1.25,1.25)
ax.xlabel(Time, t)
ax.ylabel(y(t))


plt.show()
------------------


[1;31m---------------------------------------------------------------------------[0m
[1;31mAttributeError[0m                            Traceback (most recent call last)
Cell [1;32mIn[3], line 20[0m
[0;32m     18[0m ax[38;5;241m.[39mplot(t, fsq, [38;5;124m'[39m[38;5;124mr[39m[38;5;124m'[39m,lw[38;5;241m=[39m[38;5;241m1[39m, label[38;5;241m=[39m[38;5;124m'[39m[38;5;124mFourier series, n=10[39m[38;5;124m'[39m)
[0;32m     19[0m ax[38;5;241m.[39mset_ylim([38;5;241m-[39m[38;5;241m1.25[39m,[38;5;241m1.25[39m)
[1;32m---> 20[0m [43max[49m[38;5;241;43m.[39;49m[43mxlabel[49m(Time, t)
[0;32m     21[0m ax[38;5;241m.[39mylabel(y(t))
[0;32m     24[0m plt[38;5;241m.[39mshow()

[1;31mAttributeError[0m: 'Axes' object has no attribute 'xlabel'

