Traceback (most recent call last):
  File "/Users/kjersti.daae/Library/CloudStorage/OneDrive-UniversityofBergen/KDA/Courses/GEOF211/GEOF211_compendium/.venv/lib/python3.9/site-packages/jupyter_core/utils/__init__.py", line 154, in wrapped
    asyncio.get_running_loop()
RuntimeError: no running event loop

During handling of the above exception, another exception occurred:

Traceback (most recent call last):
  File "/Users/kjersti.daae/Library/CloudStorage/OneDrive-UniversityofBergen/KDA/Courses/GEOF211/GEOF211_compendium/.venv/lib/python3.9/site-packages/jupyter_cache/executors/utils.py", line 58, in single_nb_execution
    executenb(
  File "/Users/kjersti.daae/Library/CloudStorage/OneDrive-UniversityofBergen/KDA/Courses/GEOF211/GEOF211_compendium/.venv/lib/python3.9/site-packages/nbclient/client.py", line 1319, in execute
    return NotebookClient(nb=nb, resources=resources, km=km, **kwargs).execute()
  File "/Users/kjersti.daae/Library/CloudStorage/OneDrive-UniversityofBergen/KDA/Courses/GEOF211/GEOF211_compendium/.venv/lib/python3.9/site-packages/jupyter_core/utils/__init__.py", line 158, in wrapped
    return loop.run_until_complete(inner)
  File "/Library/Developer/CommandLineTools/Library/Frameworks/Python3.framework/Versions/3.9/lib/python3.9/asyncio/base_events.py", line 642, in run_until_complete
    return future.result()
  File "/Users/kjersti.daae/Library/CloudStorage/OneDrive-UniversityofBergen/KDA/Courses/GEOF211/GEOF211_compendium/.venv/lib/python3.9/site-packages/nbclient/client.py", line 709, in async_execute
    await self.async_execute_cell(
  File "/Users/kjersti.daae/Library/CloudStorage/OneDrive-UniversityofBergen/KDA/Courses/GEOF211/GEOF211_compendium/.venv/lib/python3.9/site-packages/nbclient/client.py", line 1062, in async_execute_cell
    await self._check_raise_for_error(cell, cell_index, exec_reply)
  File "/Users/kjersti.daae/Library/CloudStorage/OneDrive-UniversityofBergen/KDA/Courses/GEOF211/GEOF211_compendium/.venv/lib/python3.9/site-packages/nbclient/client.py", line 918, in _check_raise_for_error
    raise CellExecutionError.from_cell_and_msg(cell, exec_reply_content)
nbclient.exceptions.CellExecutionError: An error occurred while executing the following cell:
------------------
import numpy as np
import matplotlib.pyplot as plt

N     = 30       # Number of time steps
M     = 100      # Number of grid points
a     = 0.75     # Propagation speed

dt = 0.01
dx = 1/M

print("Number of time steps = {:d}".format(N))
print("Number of grid points = {:d}".format(M))
print("Time step = {:f}".format(dt))
print("Grid size = {:f}".format(dx))
print("CFL number = {:f}".format(a*dt/dx))

# Grid points
X=np.linspace(0,1,M)

# Integrate the initial condition N time steps
U=LaxWendroff(topHat(X),a,dt,dx,N,M)
------------------


[0;31m---------------------------------------------------------------------------[0m
[0;31mModuleNotFoundError[0m                       Traceback (most recent call last)
Cell [0;32mIn[3], line 1[0m
[0;32m----> 1[0m [38;5;28;01mimport[39;00m[38;5;250m [39m[38;5;21;01mnumpy[39;00m[38;5;250m [39m[38;5;28;01mas[39;00m[38;5;250m [39m[38;5;21;01mnp[39;00m
[1;32m      2[0m [38;5;28;01mimport[39;00m[38;5;250m [39m[38;5;21;01mmatplotlib[39;00m[38;5;21;01m.[39;00m[38;5;21;01mpyplot[39;00m[38;5;250m [39m[38;5;28;01mas[39;00m[38;5;250m [39m[38;5;21;01mplt[39;00m
[1;32m      4[0m N     [38;5;241m=[39m [38;5;241m30[39m       [38;5;66;03m# Number of time steps[39;00m

[0;31mModuleNotFoundError[0m: No module named 'numpy'

